<?xml version="1.0"?>

<robot name="Two_Wheel_robot">

    <material name="grey">
        <color rgba="1 1 1 1"/>
    </material>
    <material name="green">
        <color rgba="0.0 1 0.0 0.8"/>
    </material>

    <link name="base_link">
        <visual>
            <geometry>
                <box size="0.6 0.4 0.2"/>
            </geometry>
            <origin xyz="0 0 0.1" rpy="0 0 0"/>
            <material name="green"/>
        </visual>
    </link>


    <link name="right_wheel">
        <visual>
            <geometry>
                <cylinder radius="0.1" length="0.05"/>
            </geometry>
            <origin xyz="0 0 0" rpy ="-1.57 0 0"/>
            <material name="grey"/>
        </visual>
    </link>


    <link name="left_wheel">
        <visual>
            <geometry>
                <cylinder radius="0.1" length="0.05"/>
            </geometry>
            <origin xyz="0 0 0" rpy="1.57 0 0"/>
            <material name="grey"/>
        </visual>
    </link>


    <link name="caster_wheel">
        <visual>
            <geometry>
                <sphere radius="0.05"/>
            </geometry>
            <origin xyz="0 0 0" rpy="0 0 0"/>
            <material name="grey"/>
        </visual>
    </link>


    <link name="base footprint"/>

    <!-- joints! -->

    <joint name="base_with_rightWheel" type="continuous">
        <parent link="base_link"/>
        <child link="right_wheel"/>
        <origin xyz="-0.15 -0.225 0.0" rpy="0.0 0.0 0.0"/>
        <axis xyz="0.0 1 0.0"/>
    </joint>

    <joint name="base_with_leftWheel" type="continuous">
        <parent link="base_link"/>
        <child link="left_wheel"/>
        <origin xyz="-0.15 0.225 0.0" rpy="0.0 0.0 0.0"/>
        <axis xyz="0.0 1 0.0"/>
    </joint>

    <joint name="base_with_caster" type="fixed">
        <parent link="base_link"/>
        <child link="caster_wheel"/>
        <origin xyz="0.2 0.0 -0.05" rpy="0.0 0.0 0.0"/>
    </joint>

    <joint name="base_joint" type="fixed">
        <parent link="base_link"/>
        <child link="base footprint"/>
        <origin xyz="0.0 0.0 -0.05" rpy="0.0 0.0 0.0"/>
    </joint>


</robot>